Workbook

Sheet MATRIZ CARTA
B2: MATRIZ DE COSTOS
E3: CARTA | K3: SUGERIDO COSTOS | N3: PRECIO FINAL
B4: ENTRADAS | C4: DESCRIPCION | D4: COSTO | E4: VENTA | F4: ICO 8% | G4: BASE | H4: % | I4: RENTABILIDAD | J4: ROTACION | K4: PRECIO SUGERIDO | L4: ICO2 | M4: CARTA | N4: PRECIO N | O4: ICO 8%2 | P4: CARTA | Q4: % | R4: RATION | S4: Incremento 13% | T4: Costo2
A5: 1 | B5: =+ENTRADAS!B88 -> PATACONES MAREA | C5: Patacones de camarones y mango sobre suero costeño. | D5: =+ENTRADAS!K93 -> 7899.1315 | E5: =+ENTRADAS!K94 -> 35000 | F5: =+E5/1.08*0.08 -> 2592.5926 | G5: =+Tabla55[[#This Row],[VENTA]]-Tabla55[[#This Row],[ICO 8%]] -> 32407.407 | H5: =+Tabla55[[#This Row],[COSTO]]/Tabla55[[#This Row],[BASE]] -> 0.24374463 | I5: =+Tabla55[[#This Row],[BASE]]/Tabla55[[#This Row],[COSTO]] -> 4.1026545 | J5: =+VLOOKUP(Tabla55[[#This Row],[ENTRADAS]],#REF!,2,0) -> #REF! | K5: =+D5/(100-65)*100 -> 22568.947 | L5: =+K5/1.08*0.08 -> 1671.7739 | M5: =+Tabla55[[#This Row],[PRECIO SUGERIDO]]+Tabla55[[#This Row],[ICO2]] -> 24240.721 | N5: 35000 | O5: =+N5/1.08*0.08 -> 2592.5926 | P5: =+N5-O5 -> 32407.407 | Q5: =+D5/P5 -> 0.24374463 | R5: =+P5/D5 -> 4.1026545 | S5: 37000 | T5: =+Tabla55[[#This Row],[COSTO]]/Tabla55[[#This Row],[Incremento 13%]] -> 0.21349004
A6: 2 | B6: =+ENTRADAS!B147 -> TACO DE POSTA | D6: =+ENTRADAS!K150 -> 6949.769 | E6: =+ENTRADAS!K151 -> 0 | F6: =+E6/1.08*0.08 -> 0 | G6: =+Tabla55[[#This Row],[VENTA]]-Tabla55[[#This Row],[ICO 8%]] -> 0 | I6: =+Tabla55[[#This Row],[BASE]]/Tabla55[[#This Row],[COSTO]] -> 0 | J6: =+VLOOKUP(Tabla55[[#This Row],[ENTRADAS]],#REF!,2,0) -> #REF! | K6: =+D6/(100-65)*100 -> 19856.483 | L6: =+K6/1.08*0.08 -> 1470.8506 | M6: =+Tabla55[[#This Row],[PRECIO SUGERIDO]]+Tabla55[[#This Row],[ICO2]] -> 21327.333 | N6: =+Tabla55[[#This Row],[VENTA]] -> 0 | O6: =+N6/1.08*0.08 -> 0 | P6: =+N6-O6 -> 0 | Q6: =+D6/P6 -> #DIV/0! | R6: =+P6/D6 -> 0 | S6: =+Tabla55[[#This Row],[VENTA]]*13%+Tabla55[[#This Row],[VENTA]] -> 0 | T6: =+Tabla55[[#This Row],[COSTO]]/Tabla55[[#This Row],[Incremento 13%]] -> #DIV/0!
A7: 3 | B7: =+ENTRADAS!B159 -> TACO DE CHICHARRON | D7: =+ENTRADAS!K162 -> 4248.9094 | E7: =+ENTRADAS!K163 -> 0 | F7: =+E7/1.08*0.08 -> 0 | G7: =+Tabla55[[#This Row],[VENTA]]-Tabla55[[#This Row],[ICO 8%]] -> 0 | I7: =+Tabla55[[#This Row],[BASE]]/Tabla55[[#This Row],[COSTO]] -> 0 | J7: =+VLOOKUP(Tabla55[[#This Row],[ENTRADAS]],#REF!,2,0) -> #REF! | K7: =+D7/(100-65)*100 -> 12139.741 | L7: =+K7/1.08*0.08 -> 899.24008 | M7: =+Tabla55[[#This Row],[PRECIO SUGERIDO]]+Tabla55[[#This Row],[ICO2]] -> 13038.981 | N7: =+Tabla55[[#This Row],[VENTA]] -> 0 | O7: =+N7/1.08*0.08 -> 0 | P7: =+N7-O7 -> 0 | Q7: =+D7/P7 -> #DIV/0! | R7: =+P7/D7 -> 0 | S7: =+Tabla55[[#This Row],[VENTA]]*13%+Tabla55[[#This Row],[VENTA]] -> 0 | T7: =+Tabla55[[#This Row],[COSTO]]/Tabla55[[#This Row],[Incremento 13%]] -> #DIV/0!
A8: 4 | B8: =+ENTRADAS!B131 -> TACO DE CAMARONES | D8: =+ENTRADAS!K134 -> 3630.8447 | E8: =+ENTRADAS!K135 -> 0 | F8: =+E8/1.08*0.08 -> 0 | G8: =+Tabla55[[#This Row],[VENTA]]-Tabla55[[#This Row],[ICO 8%]] -> 0 | I8: =+Tabla55[[#This Row],[BASE]]/Tabla55[[#This Row],[COSTO]] -> 0 | J8: =+VLOOKUP(Tabla55[[#This Row],[ENTRADAS]],#REF!,2,0) -> #REF! | K8: =+D8/(100-65)*100 -> 10373.842 | L8: =+K8/1.08*0.08 -> 768.43274 | M8: =+Tabla55[[#This Row],[PRECIO SUGERIDO]]+Tabla55[[#This Row],[ICO2]] -> 11142.275 | N8: =+Tabla55[[#This Row],[VENTA]] -> 0 | O8: =+N8/1.08*0.08 -> 0 | P8: =+N8-O8 -> 0 | Q8: =+D8/P8 -> #DIV/0! | R8: =+P8/D8 -> 0 | S8: =+Tabla55[[#This Row],[VENTA]]*13%+Tabla55[[#This Row],[VENTA]] -> 0 | T8: =+Tabla55[[#This Row],[COSTO]]/Tabla55[[#This Row],[Incremento 13%]] -> #DIV/0!
A9: 5 | B9: =+ENTRADAS!B115 -> TACO DE PESCADO | D9: =+ENTRADAS!K118 -> 3420.6682 | E9: =+ENTRADAS!K119 -> 0 | F9: =+E9/1.08*0.08 -> 0 | G9: =+Tabla55[[#This Row],[VENTA]]-Tabla55[[#This Row],[ICO 8%]] -> 0 | I9: =+Tabla55[[#This Row],[BASE]]/Tabla55[[#This Row],[COSTO]] -> 0 | J9: =+VLOOKUP(Tabla55[[#This Row],[ENTRADAS]],#REF!,2,0) -> #REF! | K9: =+D9/(100-65)*100 -> 9773.3378 | L9: =+K9/1.08*0.08 -> 723.95095 | M9: =+Tabla55[[#This Row],[PRECIO SUGERIDO]]+Tabla55[[#This Row],[ICO2]] -> 10497.289 | N9: =+Tabla55[[#This Row],[VENTA]] -> 0 | O9: =+N9/1.08*0.08 -> 0 | P9: =+N9-O9 -> 0 | Q9: =+D9/P9 -> #DIV/0! | R9: =+P9/D9 -> 0 | S9: =+Tabla55[[#This Row],[VENTA]]*13%+Tabla55[[#This Row],[VENTA]] -> 0 | T9: =+Tabla55[[#This Row],[COSTO]]/Tabla55[[#This Row],[Incremento 13%]] -> #DIV/0!
A10: 6 | B10: =+ENTRADAS!B251 -> NACHOS MARINEROS | D10: =+ENTRADAS!K254 -> 15446.887 | E10: =+ENTRADAS!K255 -> 49000 | F10: =+E10/1.08*0.08 -> 3629.6296 | G10: =+Tabla55[[#This Row],[VENTA]]-Tabla55[[#This Row],[ICO 8%]] -> 45370.37 | H10: =+Tabla55[[#This Row],[COSTO]]/Tabla55[[#This Row],[BASE]] -> 0.34046199 | I10: =+Tabla55[[#This Row],[BASE]]/Tabla55[[#This Row],[COSTO]] -> 2.9371854 | J10: =+VLOOKUP(Tabla55[[#This Row],[ENTRADAS]],#REF!,2,0) -> #REF! | K10: =+D10/(100-65)*100 -> 44133.962 | L10: =+K10/1.08*0.08 -> 3269.1823 | M10: =+Tabla55[[#This Row],[PRECIO SUGERIDO]]+Tabla55[[#This Row],[ICO2]] -> 47403.144 | N10: 49000 | O10: =+N10/1.08*0.08 -> 3629.6296 | P10: =+N10-O10 -> 45370.37 | Q10: =+D10/P10 -> 0.34046199 | R10: =+P10/D10 -> 2.9371854 | S10: 55000 | T10: =+Tabla55[[#This Row],[COSTO]]/Tabla55[[#This Row],[Incremento 13%]] -> 0.28085248
A11: 7 | B11: =+ENTRADAS!B170 -> CHICHARRONES CARIBEÃ‘OS | C11: Cubos crocantes de chicharrón acompañados con ensalada a la criolla y papas nativas en chimichurri acevichadas al cilantro. | D11: =+ENTRADAS!K173 -> 13198.324 | E11: =+ENTRADAS!K174 -> 39000 | F11: =+E11/1.08*0.08 -> 2888.8889 | G11: =+Tabla55[[#This Row],[VENTA]]-Tabla55[[#This Row],[ICO 8%]] -> 36111.111 | H11: =+Tabla55[[#This Row],[COSTO]]/Tabla55[[#This Row],[BASE]] -> 0.36549205 | I11: =+Tabla55[[#This Row],[BASE]]/Tabla55[[#This Row],[COSTO]] -> 2.7360376 | J11: =+VLOOKUP(Tabla55[[#This Row],[ENTRADAS]],#REF!,2,0) -> #REF! | K11: =+D11/(100-65)*100 -> 37709.497 | L11: =+K11/1.08*0.08 -> 2793.2961 | M11: =+Tabla55[[#This Row],[PRECIO SUGERIDO]]+Tabla55[[#This Row],[ICO2]] -> 40502.793 | N11: 42000 | O11: =+N11/1.08*0.08 -> 3111.1111 | P11: =+N11-O11 -> 38888.889 | Q11: =+D11/P11 -> 0.33938547 | R11: =+P11/D11 -> 2.9465021 | S11: 44000 | T11: =+Tabla55[[#This Row],[COSTO]]/Tabla55[[#This Row],[Incremento 13%]] -> 0.29996191
A12: 8 | B12: =+ENTRADAS!B67 -> PICADA DE MAR | C12: Crocantes anillos de calamar, camarones, palmito y pescado blanco en panko con chips de plátano con topping de cebolla acevichada y salsa de la casa, perfecto para compartir | D12: =+ENTRADAS!K70 -> 14827.464 | E12: =+ENTRADAS!K71 -> 49000 | F12: =+E12/1.08*0.08 -> 3629.6296 | G12: =+Tabla55[[#This Row],[VENTA]]-Tabla55[[#This Row],[ICO 8%]] -> 45370.37 | H12: =+Tabla55[[#This Row],[COSTO]]/Tabla55[[#This Row],[BASE]] -> 0.32680942 | I12: =+Tabla55[[#This Row],[BASE]]/Tabla55[[#This Row],[COSTO]] -> 3.0598873 | J12: =+VLOOKUP(Tabla55[[#This Row],[ENTRADAS]],#REF!,2,0) -> #REF! | K12: =+D12/(100-65)*100 -> 42364.184 | L12: =+K12/1.08*0.08 -> 3138.0877 | M12: =+Tabla55[[#This Row],[PRECIO SUGERIDO]]+Tabla55[[#This Row],[ICO2]] -> 45502.272 | N12: 49000 | O12: =+N12/1.08*0.08 -> 3629.6296 | P12: =+N12-O12 -> 45370.37 | Q12: =+D12/P12 -> 0.32680942 | R12: =+P12/D12 -> 3.0598873 | S12: 55000 | T12: =+Tabla55[[#This Row],[COSTO]]/Tabla55[[#This Row],[Incremento 13%]] -> 0.26959026
A13: 9 | B13: =+ENTRADAS!B219 -> TACO TIERRA | C13: Tortilla de maíz, base de guacamole, posta cartagenera con toping de piñas caramelizadas con ron de coco y chicharrón crocante con pico de gallo. | D13: =+ENTRADAS!K222 -> 9012.4208 | E13: =+ENTRADAS!K223 -> 35000 | F13: =+E13/1.08*0.08 -> 2592.5926 | G13: =+Tabla55[[#This Row],[VENTA]]-Tabla55[[#This Row],[ICO 8%]] -> 32407.407 | H13: =+Tabla55[[#This Row],[COSTO]]/Tabla55[[#This Row],[BASE]] -> 0.27809756 | I13: =+Tabla55[[#This Row],[BASE]]/Tabla55[[#This Row],[COSTO]] -> 3.5958604 | J13: =+VLOOKUP(Tabla55[[#This Row],[ENTRADAS]],#REF!,2,0) -> #REF! | K13: =+D13/(100-65)*100 -> 25749.774 | L13: =+K13/1.08*0.08 -> 1907.3906 | M13: =+Tabla55[[#This Row],[PRECIO SUGERIDO]]+Tabla55[[#This Row],[ICO2]] -> 27657.164 | N13: 35000 | O13: =+N13/1.08*0.08 -> 2592.5926 | P13: =+N13-O13 -> 32407.407 | Q13: =+D13/P13 -> 0.27809756 | R13: =+P13/D13 -> 3.5958604 | S13: 38000 | T13: =+Tabla55[[#This Row],[COSTO]]/Tabla55[[#This Row],[Incremento 13%]] -> 0.23716897
A14: 10 | B14: =+ENTRADAS!B49 -> GRATINADO DE SETAS | C14: Champiñones portobello, orellanas y paris en salsa de queso fundido al vino blanco, acompañado de pan baguette. | D14: =+ENTRADAS!K52 -> 9691.7024 | E14: =+ENTRADAS!K53 -> 39000 | F14: =+E14/1.08*0.08 -> 2888.8889 | G14: =+Tabla55[[#This Row],[VENTA]]-Tabla55[[#This Row],[ICO 8%]] -> 36111.111 | H14: =+Tabla55[[#This Row],[COSTO]]/Tabla55[[#This Row],[BASE]] -> 0.2683856 | I14: =+Tabla55[[#This Row],[BASE]]/Tabla55[[#This Row],[COSTO]] -> 3.7259823 | J14: =+VLOOKUP(Tabla55[[#This Row],[ENTRADAS]],#REF!,2,0) -> #REF! | K14: =+D14/(100-65)*100 -> 27690.578 | L14: =+K14/1.08*0.08 -> 2051.1539 | M14: =+Tabla55[[#This Row],[PRECIO SUGERIDO]]+Tabla55[[#This Row],[ICO2]] -> 29741.732 | N14: 39000 | O14: =+N14/1.08*0.08 -> 2888.8889 | P14: =+N14-O14 -> 36111.111 | Q14: =+D14/P14 -> 0.2683856 | R14: =+P14/D14 -> 3.7259823 | S14: 44000 | T14: =+Tabla55[[#This Row],[COSTO]]/Tabla55[[#This Row],[Incremento 13%]] -> 0.22026596
A15: 11 | B15: =+ENTRADAS!B188 -> PULPO PARRILLADO | C15: Pulpo salteado con vegetales, papas criollas crocantes y suero costeño. | D15: =+ENTRADAS!K191 -> 20520.493 | E15: =+ENTRADAS!K192 -> 85000 | F15: =+E15/1.08*0.08 -> 6296.2963 | G15: =+Tabla55[[#This Row],[VENTA]]-Tabla55[[#This Row],[ICO 8%]] -> 78703.704 | H15: =+Tabla55[[#This Row],[COSTO]]/Tabla55[[#This Row],[BASE]] -> 0.26073097 | I15: =+Tabla55[[#This Row],[BASE]]/Tabla55[[#This Row],[COSTO]] -> 3.835371 | J15: =+VLOOKUP(Tabla55[[#This Row],[ENTRADAS]],#REF!,2,0) -> #REF! | K15: =+D15/(100-65)*100 -> 58629.979 | L15: =+K15/1.08*0.08 -> 4342.9614 | M15: =+Tabla55[[#This Row],[PRECIO SUGERIDO]]+Tabla55[[#This Row],[ICO2]] -> 62972.941 | N15: 85000 | O15: =+N15/1.08*0.08 -> 6296.2963 | P15: =+N15-O15 -> 78703.704 | Q15: =+D15/P15 -> 0.26073097 | R15: =+P15/D15 -> 3.835371 | S15: 92000 | T15: =+Tabla55[[#This Row],[COSTO]]/Tabla55[[#This Row],[Incremento 13%]] -> 0.22304883
A16: 12 | B16: =+ENTRADAS!B233 -> TACO MIXTO | C16: Taco de mar y taco de tierra a elección. | D16: =+ENTRADAS!K236 -> 8362.9656 | E16: =+ENTRADAS!K237 -> 35000 | F16: =+E16/1.08*0.08 -> 2592.5926 | G16: =+Tabla55[[#This Row],[VENTA]]-Tabla55[[#This Row],[ICO 8%]] -> 32407.407 | H16: =+Tabla55[[#This Row],[COSTO]]/Tabla55[[#This Row],[BASE]] -> 0.25805722 | I16: =+Tabla55[[#This Row],[BASE]]/Tabla55[[#This Row],[COSTO]] -> 3.8751095 | J16: =+VLOOKUP(Tabla55[[#This Row],[ENTRADAS]],#REF!,2,0) -> #REF! | K16: =+D16/(100-65)*100 -> 23894.187 | L16: =+K16/1.08*0.08 -> 1769.9398 | M16: =+Tabla55[[#This Row],[PRECIO SUGERIDO]]+Tabla55[[#This Row],[ICO2]] -> 25664.127 | N16: 35000 | O16: =+N16/1.08*0.08 -> 2592.5926 | P16: =+N16-O16 -> 32407.407 | Q16: =+D16/P16 -> 0.25805722 | R16: =+P16/D16 -> 3.8751095 | S16: 38000 | T16: =+Tabla55[[#This Row],[COSTO]]/Tabla55[[#This Row],[Incremento 13%]] -> 0.22007804
A17: 13 | B17: =+ENTRADAS!B6 -> BOCADOS DEL ORIENTE | C17: Palmitos crocantes rellenos de salsa dinamita, acompañados de salsa melcocha. | D17: =+ENTRADAS!K9 -> 6412.5787 | E17: =+ENTRADAS!K10 -> 31000 | F17: =+E17/1.08*0.08 -> 2296.2963 | G17: =+Tabla55[[#This Row],[VENTA]]-Tabla55[[#This Row],[ICO 8%]] -> 28703.704 | H17: =+Tabla55[[#This Row],[COSTO]]/Tabla55[[#This Row],[BASE]] -> 0.22340597 | I17: =+Tabla55[[#This Row],[BASE]]/Tabla55[[#This Row],[COSTO]] -> 4.4761562 | J17: =+VLOOKUP(Tabla55[[#This Row],[ENTRADAS]],#REF!,2,0) -> #REF! | K17: =+D17/(100-65)*100 -> 18321.653 | L17: =+K17/1.08*0.08 -> 1357.1595 | M17: =+Tabla55[[#This Row],[PRECIO SUGERIDO]]+Tabla55[[#This Row],[ICO2]] -> 19678.813 | N17: 31000 | O17: =+N17/1.08*0.08 -> 2296.2963 | P17: =+N17-O17 -> 28703.704 | Q17: =+D17/P17 -> 0.22340597 | R17: =+P17/D17 -> 4.4761562 | S17: 35000 | T17: =+Tabla55[[#This Row],[COSTO]]/Tabla55[[#This Row],[Incremento 13%]] -> 0.18321653
A18: 14 | B18: =+ENTRADAS!B17 -> DEDOS DE QUESO COSTEÃ‘O | C18: Queso costeño frito acompañado de mermelada de ají. | D18: =+ENTRADAS!K20 -> 5327.9285 | E18: =+ENTRADAS!K21 -> 26000 | F18: =+E18/1.08*0.08 -> 1925.9259 | G18: =+Tabla55[[#This Row],[VENTA]]-Tabla55[[#This Row],[ICO 8%]] -> 24074.074 | H18: =+Tabla55[[#This Row],[COSTO]]/Tabla55[[#This Row],[BASE]] -> 0.22131395 | I18: =+Tabla55[[#This Row],[BASE]]/Tabla55[[#This Row],[COSTO]] -> 4.5184679 | J18: =+VLOOKUP(Tabla55[[#This Row],[ENTRADAS]],#REF!,2,0) -> #REF! | K18: =+D18/(100-65)*100 -> 15222.653 | L18: =+K18/1.08*0.08 -> 1127.6039 | M18: =+Tabla55[[#This Row],[PRECIO SUGERIDO]]+Tabla55[[#This Row],[ICO2]] -> 16350.257 | N18: 26000 | O18: =+N18/1.08*0.08 -> 1925.9259 | P18: =+N18-O18 -> 24074.074 | Q18: =+D18/P18 -> 0.22131395 | R18: =+P18/D18 -> 4.5184679 | S18: 29000 | T18: =+Tabla55[[#This Row],[COSTO]]/Tabla55[[#This Row],[Incremento 13%]] -> 0.18372167
A19: 15 | B19: =+ENTRADAS!B205 -> TACO DE MAR | C19: Tortilla de maíz, mézclum con aceite de trufa, camarones apanados y pescado tempurizado con vinagreta mediterránea y salsa tártara. | D19: =+ENTRADAS!K208 -> 6981.1971 | E19: =+ENTRADAS!K209 -> 35000 | F19: =+E19/1.08*0.08 -> 2592.5926 | G19: =+Tabla55[[#This Row],[VENTA]]-Tabla55[[#This Row],[ICO 8%]] -> 32407.407 | H19: =+Tabla55[[#This Row],[COSTO]]/Tabla55[[#This Row],[BASE]] -> 0.2154198 | I19: =+Tabla55[[#This Row],[BASE]]/Tabla55[[#This Row],[COSTO]] -> 4.6420989 | J19: =+VLOOKUP(Tabla55[[#This Row],[ENTRADAS]],#REF!,2,0) -> #REF! | K19: =+D19/(100-65)*100 -> 19946.278 | L19: =+K19/1.08*0.08 -> 1477.502 | M19: =+Tabla55[[#This Row],[PRECIO SUGERIDO]]+Tabla55[[#This Row],[ICO2]] -> 21423.78 | N19: 35000 | O19: =+N19/1.08*0.08 -> 2592.5926 | P19: =+N19-O19 -> 32407.407 | Q19: =+D19/P19 -> 0.2154198 | R19: =+P19/D19 -> 4.6420989 | S19: 38000 | T19: =+Tabla55[[#This Row],[COSTO]]/Tabla55[[#This Row],[Incremento 13%]] -> 0.18371571
A20: 16 | B20: =+ENTRADAS!B29 -> GRATINADO DE JAIBA | C20: Carne de cangrejo gratinada en salsa de la casa acompañada de pan baguette. | D20: =+ENTRADAS!K32 -> 7468.0028 | E20: =+ENTRADAS!K33 -> 41000 | F20: =+E20/1.08*0.08 -> 3037.037 | G20: =+Tabla55[[#This Row],[VENTA]]-Tabla55[[#This Row],[ICO 8%]] -> 37962.963 | H20: =+Tabla55[[#This Row],[COSTO]]/Tabla55[[#This Row],[BASE]] -> 0.19671812 | I20: =+Tabla55[[#This Row],[BASE]]/Tabla55[[#This Row],[COSTO]] -> 5.0834157 | J20: =+VLOOKUP(Tabla55[[#This Row],[ENTRADAS]],#REF!,2,0) -> #REF! | K20: =+D20/(100-65)*100 -> 21337.151 | L20: =+K20/1.08*0.08 -> 1580.5297 | M20: =+Tabla55[[#This Row],[PRECIO SUGERIDO]]+Tabla55[[#This Row],[ICO2]] -> 22917.681 | N20: 41000 | O20: =+N20/1.08*0.08 -> 3037.037 | P20: =+N20-O20 -> 37962.963 | Q20: =+D20/P20 -> 0.19671812 | R20: =+P20/D20 -> 5.0834157 | S20: 46000 | T20: =+Tabla55[[#This Row],[COSTO]]/Tabla55[[#This Row],[Incremento 13%]] -> 0.16234789
B21: =+ENTRADAS!B103 -> CROQUETAS CREMOSA DE JAIBA | C21: Croqueta cremosa de carne de cangrejo al estilo español | D21: =+ENTRADAS!K106 -> 4572.1884 | E21: =+ENTRADAS!K107 -> 35000 | F21: =+E21/1.08*0.08 -> 2592.5926 | G21: =+Tabla55[[#This Row],[VENTA]]-Tabla55[[#This Row],[ICO 8%]] -> 32407.407 | H21: =+Tabla55[[#This Row],[COSTO]]/Tabla55[[#This Row],[BASE]] -> 0.14108467 | I21: =+Tabla55[[#This Row],[BASE]]/Tabla55[[#This Row],[COSTO]] -> 7.0879423 | J21: =+VLOOKUP(Tabla55[[#This Row],[ENTRADAS]],#REF!,2,0) -> #REF! | K21: =+D21/(100-65)*100 -> 13063.395 | L21: =+K21/1.08*0.08 -> 967.65891 | M21: =+Tabla55[[#This Row],[PRECIO SUGERIDO]]+Tabla55[[#This Row],[ICO2]] -> 14031.054 | N21: 35000 | O21: =+N21/1.08*0.08 -> 2592.5926 | P21: =+N21-O21 -> 32407.407 | Q21: =+D21/P21 -> 0.14108467 | R21: =+P21/D21 -> 7.0879423 | S21: 38000 | T21: =+Tabla55[[#This Row],[COSTO]]/Tabla55[[#This Row],[Incremento 13%]] -> 0.12032075
B22: Total | H22: =SUBTOTAL(101,Tabla55[%]) -> 0.25690169 | J22: =SUBTOTAL(109,Tabla55[ROTACION]) -> #REF! | R22: =SUBTOTAL(109,Tabla55[RATION]) -> 53.886634
E26: CARTA | K26: SUGERIDO COSTOS | N26: PRECIO FINAL
B27: LOS ARREBATOS DEL CHEF | C27: DESCRIPCION | D27: COSTO | E27: VENTA | F27: ICO 8% | G27: BASE | H27: % | I27: RENTABILIDAD | J27: ROTACION | K27: PRECIO SUGERIDO | L27: ICO2 | M27: CARTA | N27: PRECIO N | O27: ICO 8%2 | P27: CARTA | Q27: % | R27: RATION | S27: Incremento 13% | T27: Costo2
A28: 1 | B28: =+'LOS ARREBATOS DEL CHEF'!B5 -> PESCA MALANGA | D28: =+'LOS ARREBATOS DEL CHEF'!K8 -> 25181.786 | E28: 66000 | F28: =+E28/1.08*0.08 -> 4888.8889 | G28: =+Tabla5557319[[#This Row],[VENTA]]-Tabla5557319[[#This Row],[ICO 8%]] -> 61111.111 | H28: =+Tabla5557319[[#This Row],[COSTO]]/Tabla5557319[[#This Row],[BASE]] -> 0.41206559 | I28: =+Tabla5557319[[#This Row],[BASE]]/Tabla5557319[[#This Row],[COSTO]] -> 2.4267981 | J28: =+VLOOKUP(Tabla5557319[[#This Row],[LOS ARREBATOS DEL CHEF]],#REF!,2,0) -> #REF! | K28: =+D28/(100-65)*100 -> 71947.96 | L28: =+K28/1.08*0.08 -> 5329.4785 | M28: =+Tabla5557319[[#This Row],[PRECIO SUGERIDO]]+Tabla5557319[[#This Row],[ICO2]] -> 77277.438 | N28: 66000 | O28: =+N28/1.08*0.08 -> 4888.8889 | P28: =+N28-O28 -> 61111.111 | Q28: =+D28/P28 -> 0.41206559 | R28: =+P28/D28 -> 2.4267981 | S28: 79000 | T28: =+Tabla5557319[[#This Row],[COSTO]]/Tabla5557319[[#This Row],[Incremento 13%]] -> 0.31875678
A29: 2 | B29: =+'LOS ARREBATOS DEL CHEF'!B29 -> RISOTTO Y PESCA BLANCA TROPICAL | C29: Pesca en mantequilla de romero con arroz arbóreo de rocoto y coco, vejetales salteados acompañado de chips de yuca y batata | D29: =+'LOS ARREBATOS DEL CHEF'!K32 -> 21443.446 | E29: 74000 | F29: =+E29/1.08*0.08 -> 5481.4815 | G29: =+Tabla5557319[[#This Row],[VENTA]]-Tabla5557319[[#This Row],[ICO 8%]] -> 68518.519 | H29: =+Tabla5557319[[#This Row],[COSTO]]/Tabla5557319[[#This Row],[BASE]] -> 0.31295839 | I29: =+Tabla5557319[[#This Row],[BASE]]/Tabla5557319[[#This Row],[COSTO]] -> 3.1953129 | J29: =+VLOOKUP(Tabla5557319[[#This Row],[LOS ARREBATOS DEL CHEF]],#REF!,2,0) -> #REF! | K29: =+D29/(100-65)*100 -> 61266.987 | L29: =+K29/1.08*0.08 -> 4538.2953 | M29: =+Tabla5557319[[#This Row],[PRECIO SUGERIDO]]+Tabla5557319[[#This Row],[ICO2]] -> 65805.283 | N29: 74000 | O29: =+N29/1.08*0.08 -> 5481.4815 | P29: =+N29-O29 -> 68518.519 | Q29: =+D29/P29 -> 0.31295839 | R29: =+P29/D29 -> 3.1953129 | S29: 77000 | T29: =+Tabla5557319[[#This Row],[COSTO]]/Tabla5557319[[#This Row],[Incremento 13%]] -> 0.27848631
A30: 4 | B30: =+'LOS ARREBATOS DEL CHEF'!B58 -> ARROZ DEL CARIBE | C30: Farsa de contramuslo con queso y albahaca, acompañada de puré de maduro, salsa de coco y ají amarillo, crocantes de vainilla y ensalada | D30: =+'LOS ARREBATOS DEL CHEF'!K61 -> 14664.997 | E30: 54000 | F30: =+E30/1.08*0.08 -> 4000 | G30: =+Tabla5557319[[#This Row],[VENTA]]-Tabla5557319[[#This Row],[ICO 8%]] -> 50000 | H30: =+Tabla5557319[[#This Row],[COSTO]]/Tabla5557319[[#This Row],[BASE]] -> 0.29329993 | I30: =+Tabla5557319[[#This Row],[BASE]]/Tabla5557319[[#This Row],[COSTO]] -> 3.4094791 | J30: =+VLOOKUP(Tabla5557319[[#This Row],[LOS ARREBATOS DEL CHEF]],#REF!,2,0) -> #REF! | K30: =+D30/(100-65)*100 -> 41899.99 | L30: =+K30/1.08*0.08 -> 3103.703 | M30: =+Tabla5557319[[#This Row],[PRECIO SUGERIDO]]+Tabla5557319[[#This Row],[ICO2]] -> 45003.693 | N30: 54000 | O30: =+N30/1.08*0.08 -> 4000 | P30: =+N30-O30 -> 50000 | Q30: =+D30/P30 -> 0.29329993 | R30: =+P30/D30 -> 3.4094791 | S30: 61000 | T30: =+Tabla5557319[[#This Row],[COSTO]]/Tabla5557319[[#This Row],[Incremento 13%]] -> 0.24040978
B31: =+'LOS ARREBATOS DEL CHEF'!B76 -> SOPA DE CANGREJO | D31: =+'LOS ARREBATOS DEL CHEF'!K79 -> 17987.894 | F31: =+E31/1.08*0.08 -> 0 | G31: =+Tabla5557319[[#This Row],[VENTA]]-Tabla5557319[[#This Row],[ICO 8%]] -> 0 | H31: =+Tabla5557319[[#This Row],[COSTO]]/Tabla5557319[[#This Row],[BASE]] -> #DIV/0! | I31: =+Tabla5557319[[#This Row],[BASE]]/Tabla5557319[[#This Row],[COSTO]] -> 0 | J31: =+VLOOKUP(Tabla5557319[[#This Row],[LOS ARREBATOS DEL CHEF]],#REF!,2,0) -> #REF! | K31: =+D31/(100-65)*100 -> 51393.982 | L31: =+K31/1.08*0.08 -> 3806.9617 | M31: =+Tabla5557319[[#This Row],[PRECIO SUGERIDO]]+Tabla5557319[[#This Row],[ICO2]] -> 55200.944 | O31: =+N31/1.08*0.08 -> 0 | P31: =+N31-O31 -> 0 | Q31: =+D31/P31 -> #DIV/0! | R31: =+P31/D31 -> 0 | S31: 59000 | T31: =+Tabla5557319[[#This Row],[COSTO]]/Tabla5557319[[#This Row],[Incremento 13%]] -> 0.30487956
B32: =+'LOS ARREBATOS DEL CHEF'!B95 -> GAMBAS | D32: =+'LOS ARREBATOS DEL CHEF'!K98 -> 19126.897 | F32: =+E32/1.08*0.08 -> 0 | G32: =+Tabla5557319[[#This Row],[VENTA]]-Tabla5557319[[#This Row],[ICO 8%]] -> 0 | H32: =+Tabla5557319[[#This Row],[COSTO]]/Tabla5557319[[#This Row],[BASE]] -> #DIV/0! | I32: =+Tabla5557319[[#This Row],[BASE]]/Tabla5557319[[#This Row],[COSTO]] -> 0 | J32: =+VLOOKUP(Tabla5557319[[#This Row],[LOS ARREBATOS DEL CHEF]],#REF!,2,0) -> #REF! | K32: =+D32/(100-65)*100 -> 54648.277 | L32: =+K32/1.08*0.08 -> 4048.0205 | M32: =+Tabla5557319[[#This Row],[PRECIO SUGERIDO]]+Tabla5557319[[#This Row],[ICO2]] -> 58696.297 | O32: =+N32/1.08*0.08 -> 0 | P32: =+N32-O32 -> 0 | Q32: =+D32/P32 -> #DIV/0! | R32: =+P32/D32 -> 0 | S32: 62000 | T32: =+Tabla5557319[[#This Row],[COSTO]]/Tabla5557319[[#This Row],[Incremento 13%]] -> 0.30849834
H33: =SUBTOTAL(101,Tabla5557319[%]) -> #DIV/0! | J33: =SUBTOTAL(109,Tabla5557319[ROTACION]) -> #REF! | R33: =SUBTOTAL(109,Tabla5557319[RATION]) -> 9.0315902
E36: CARTA | K36: SUGERIDO COSTOS | N36: PRECIO FINAL
B37: LANGOSTINOS | C37: DESCRIPCION | D37: COSTO | E37: VENTA | F37: ICO 8% | G37: BASE | H37: % | I37: RENTABILIDAD | J37: ROTACION | K37: PRECIO SUGERIDO | L37: ICO2 | M37: CARTA | N37: PRECIO N | O37: ICO 8%2 | P37: CARTA | Q37: % | R37: RATION | S37: Incremento 13% | T37: Costo2
A38: 1 | B38: =+LANGOSTINOS!B6 -> LANGOSTINOS ARREBATADOS | C38: Langostinos crocantes en salsa de queso al rocoto, con puré de papa a la parmesana | D38: =+LANGOSTINOS!K9 -> 16534.078 | E38: =+LANGOSTINOS!K10 -> 56000 | F38: =+E38/1.08*0.08 -> 4148.1481 | G38: =+Tabla5557[[#This Row],[VENTA]]-Tabla5557[[#This Row],[ICO 8%]] -> 51851.852 | H38: =+Tabla5557[[#This Row],[COSTO]]/Tabla5557[[#This Row],[BASE]] -> 0.3188715 | I38: =+Tabla5557[[#This Row],[BASE]]/Tabla5557[[#This Row],[COSTO]] -> 3.1360595 | J38: =+VLOOKUP(Tabla5557[[#This Row],[LANGOSTINOS]],#REF!,2,0) -> #REF! | K38: =+D38/(100-65)*100 -> 47240.222 | L38: =+K38/1.08*0.08 -> 3499.2757 | M38: =+Tabla5557[[#This Row],[PRECIO SUGERIDO]]+Tabla5557[[#This Row],[ICO2]] -> 50739.497 | N38: 56000 | O38: =+N38/1.08*0.08 -> 4148.1481 | P38: =+N38-O38 -> 51851.852 | Q38: =+D38/P38 -> 0.3188715 | R38: =+P38/D38 -> 3.1360595 | S38: 60000 | T38: =+Tabla5557[[#This Row],[COSTO]]/Tabla5557[[#This Row],[Incremento 13%]] -> 0.27556796
A39: 2 | B39: =+LANGOSTINOS!B38 -> LANGOSTINOS TIMBIQUI | C39: Langostinos crocantes albardados con tocino, sobre arroz de ají amarillo y reducción de balsámico. | D39: =+LANGOSTINOS!K41 -> 14394.66 | E39: =+LANGOSTINOS!K42 -> 59000 | F39: =+E39/1.08*0.08 -> 4370.3704 | G39: =+Tabla5557[[#This Row],[VENTA]]-Tabla5557[[#This Row],[ICO 8%]] -> 54629.63 | H39: =+Tabla5557[[#This Row],[COSTO]]/Tabla5557[[#This Row],[BASE]] -> 0.26349547 | I39: =+Tabla5557[[#This Row],[BASE]]/Tabla5557[[#This Row],[COSTO]] -> 3.7951316 | J39: =+VLOOKUP(Tabla5557[[#This Row],[LANGOSTINOS]],#REF!,2,0) -> #REF! | K39: =+D39/(100-65)*100 -> 41127.6 | L39: =+K39/1.08*0.08 -> 3046.4889 | M39: =+Tabla5557[[#This Row],[PRECIO SUGERIDO]]+Tabla5557[[#This Row],[ICO2]] -> 44174.089 | N39: 59000 | O39: =+N39/1.08*0.08 -> 4370.3704 | P39: =+N39-O39 -> 54629.63 | Q39: =+D39/P39 -> 0.26349547 | R39: =+P39/D39 -> 3.7951316 | S39: 59000 | T39: =+Tabla5557[[#This Row],[COSTO]]/Tabla5557[[#This Row],[Incremento 13%]] -> 0.24397729
A40: 3 | B40: =+LANGOSTINOS!B24 -> LANGOSTINOS EN COCO Y CURRY | C40: Langostinos al coco y curry servido sobre puré de papas, tomates perla y queso parmesano. | D40: =+LANGOSTINOS!K27 -> 13533.059 | E40: =+LANGOSTINOS!K28 -> 56000 | F40: =+E40/1.08*0.08 -> 4148.1481 | G40: =+Tabla5557[[#This Row],[VENTA]]-Tabla5557[[#This Row],[ICO 8%]] -> 51851.852 | H40: =+Tabla5557[[#This Row],[COSTO]]/Tabla5557[[#This Row],[BASE]] -> 0.26099471 | I40: =+Tabla5557[[#This Row],[BASE]]/Tabla5557[[#This Row],[COSTO]] -> 3.8314953 | J40: =+VLOOKUP(Tabla5557[[#This Row],[LANGOSTINOS]],#REF!,2,0) -> #REF! | K40: =+D40/(100-65)*100 -> 38665.883 | L40: =+K40/1.08*0.08 -> 2864.1395 | M40: =+Tabla5557[[#This Row],[PRECIO SUGERIDO]]+Tabla5557[[#This Row],[ICO2]] -> 41530.023 | N40: 56000 | O40: =+N40/1.08*0.08 -> 4148.1481 | P40: =+N40-O40 -> 51851.852 | Q40: =+D40/P40 -> 0.26099471 | R40: =+P40/D40 -> 3.8314953 | S40: 61000 | T40: =+Tabla5557[[#This Row],[COSTO]]/Tabla5557[[#This Row],[Incremento 13%]] -> 0.22185343
B41: Total | H41: =SUBTOTAL(101,Tabla5557[%]) -> 0.28112056 | J41: =SUBTOTAL(109,Tabla5557[ROTACION]) -> #REF! | R41: =SUBTOTAL(109,Tabla5557[RATION]) -> 10.762686
E44: CARTA | K44: SUGERIDO COSTOS | N44: PRECIO FINAL
B45: CEVICHES | C45: DESCRIPCION | D45: COSTO | E45: VENTA | F45: ICO 8% | G45: BASE | H45: % | I45: RENTABILIDAD | J45: ROTACION | K45: PRECIO SUGERIDO | L45: ICO2 | M45: CARTA | N45: PRECIO N | O45: ICO 8%2 | P45: CARTA | Q45: % | R45: RATION | S45: Incremento 13% | T45: Costo2
A46: 1 | B46: =+CEVICHES!B27 -> CEVICHE DE CHICHARRON | C46: Trozos crocantes de chicharrón bañados en salsa de rocoto, mix de cebollas, tomate cherry rojo, chips de plátano. | D46: =+CEVICHES!K30 -> 14183.873 | E46: =+CEVICHES!K31 -> 46000 | F46: =+E46/1.08*0.08 -> 3407.4074 | G46: =+Tabla5557273[[#This Row],[VENTA]]-Tabla5557273[[#This Row],[ICO 8%]] -> 42592.593 | H46: =+Tabla5557273[[#This Row],[COSTO]]/Tabla5557273[[#This Row],[BASE]] -> 0.33301267 | I46: =+Tabla5557273[[#This Row],[BASE]]/Tabla5557273[[#This Row],[COSTO]] -> 3.0028888 | J46: =+VLOOKUP(Tabla5557273[[#This Row],[CEVICHES]],#REF!,2,0) -> #REF! | K46: =+D46/(100-65)*100 -> 40525.351 | L46: =+K46/1.08*0.08 -> 3001.8778 | M46: =+Tabla5557273[[#This Row],[PRECIO SUGERIDO]]+Tabla5557273[[#This Row],[ICO2]] -> 43527.229 | N46: 46000 | O46: =+N46/1.08*0.08 -> 3407.4074 | P46: =+N46-O46 -> 42592.593 | Q46: =+D46/P46 -> 0.33301267 | R46: =+P46/D46 -> 3.0028888 | S46: 49000 | T46: =+Tabla5557273[[#This Row],[COSTO]]/Tabla5557273[[#This Row],[Incremento 13%]] -> 0.28946679
A47: 2 | B47: =+CEVICHES!B41 -> CEVICHE MIRAFLORES | C47: Ceviche mixto de pescado blanco y calamar marinado en leche de tigre, ají peruano, acompañado de una base de vegetales al fresco, trozos de aguacate y papas nativas. | D47: =+CEVICHES!K44 -> 16688.921 | E47: =+CEVICHES!K45 -> 48000 | F47: =+E47/1.08*0.08 -> 3555.5556 | G47: =+Tabla5557273[[#This Row],[VENTA]]-Tabla5557273[[#This Row],[ICO 8%]] -> 44444.444 | H47: =+Tabla5557273[[#This Row],[COSTO]]/Tabla5557273[[#This Row],[BASE]] -> 0.37550072 | I47: =+Tabla5557273[[#This Row],[BASE]]/Tabla5557273[[#This Row],[COSTO]] -> 2.6631108 | J47: =+VLOOKUP(Tabla5557273[[#This Row],[CEVICHES]],#REF!,2,0) -> #REF! | K47: =+D47/(100-65)*100 -> 47682.631 | L47: =+K47/1.08*0.08 -> 3532.0467 | M47: =+Tabla5557273[[#This Row],[PRECIO SUGERIDO]]+Tabla5557273[[#This Row],[ICO2]] -> 51214.677 | N47: 51000 | O47: =+N47/1.08*0.08 -> 3777.7778 | P47: =+N47-O47 -> 47222.222 | Q47: =+D47/P47 -> 0.35341244 | R47: =+P47/D47 -> 2.8295552 | S47: 54000 | T47: =+Tabla5557273[[#This Row],[COSTO]]/Tabla5557273[[#This Row],[Incremento 13%]] -> 0.30905409
A48: 3 | B48: =+CEVICHES!B6 -> COCTEL CARTAGENERO | C48: Cóctel de camarón en salsa rosada, vino blanco y piña en trozos, acompañado de patacones crocantes, brotes frescos y masago. | D48: =+CEVICHES!K9 -> 14314.865 | E48: =+CEVICHES!K10 -> 48000 | F48: =+E48/1.08*0.08 -> 3555.5556 | G48: =+Tabla5557273[[#This Row],[VENTA]]-Tabla5557273[[#This Row],[ICO 8%]] -> 44444.444 | H48: =+Tabla5557273[[#This Row],[COSTO]]/Tabla5557273[[#This Row],[BASE]] -> 0.32208446 | I48: =+Tabla5557273[[#This Row],[BASE]]/Tabla5557273[[#This Row],[COSTO]] -> 3.1047757 | J48: =+VLOOKUP(Tabla5557273[[#This Row],[CEVICHES]],#REF!,2,0) -> #REF! | K48: =+D48/(100-65)*100 -> 40899.614 | L48: =+K48/1.08*0.08 -> 3029.601 | M48: =+Tabla5557273[[#This Row],[PRECIO SUGERIDO]]+Tabla5557273[[#This Row],[ICO2]] -> 43929.215 | N48: 43000 | O48: =+N48/1.08*0.08 -> 3185.1852 | P48: =+N48-O48 -> 39814.815 | Q48: =+D48/P48 -> 0.35953614 | R48: =+P48/D48 -> 2.7813616 | S48: 54000 | T48: =+Tabla5557273[[#This Row],[COSTO]]/Tabla5557273[[#This Row],[Incremento 13%]] -> 0.26509009
...

Sheet SUB RECETAS COCINA
B7: SUB. SALSA TARTARA | J7: ANALISIS RECETA | M7: Preparacion
B8: ArtÃ­culo | C8: Unidad Medida | D8: Unidades Netas | E8: % Merma | F8: Unidades | G8: Coste Componente | H8: Coste LÃ­nea | J8: COSTO DEL PLATO | K8: =SUM(Tabla1103453454455456479116117118120740126148156186[Coste LÃ­nea]) -> 7224.8993
B9: PIMENTON X KILO | C9: g | D9: 30 | E9: 0 | F9: 30 | G9: =+VLOOKUP(Tabla1103453454455456479116117118120740126148156186[[#This Row],[ArtÃ­culo]],Tabla34[#All],3,0) -> 6 | H9: =+Tabla1103453454455456479116117118120740126148156186[[#This Row],[Coste Componente]]*Tabla1103453454455456479116117118120740126148156186[[#This Row],[Unidades]] -> 180 | J9: MARGEN DE ERROR DEL 10% | K9: =+K8*5% -> 361.24497
B10: ALCAPARRA ALFRESCO X 500GR | C10: g | D10: 20 | E10: 0 | F10: 20 | G10: =+VLOOKUP(Tabla1103453454455456479116117118120740126148156186[[#This Row],[ArtÃ­culo]],Tabla34[#All],3,0) -> 27.146 | H10: =+Tabla1103453454455456479116117118120740126148156186[[#This Row],[Coste Componente]]*Tabla1103453454455456479116117118120740126148156186[[#This Row],[Unidades]] -> 542.92 | J10: COSTO + MARGEN ERROR | K10: =+K8+K9 -> 7586.1443
B11: CEBOLLA RAMA LIMPIA X KILO | C11: g | D11: 20 | E11: 0 | F11: 20 | G11: =+VLOOKUP(Tabla1103453454455456479116117118120740126148156186[[#This Row],[ArtÃ­culo]],Tabla34[#All],3,0) -> 5 | H11: =+Tabla1103453454455456479116117118120740126148156186[[#This Row],[Coste Componente]]*Tabla1103453454455456479116117118120740126148156186[[#This Row],[Unidades]] -> 100 | J11: Rendimiento | K11: 325
B12: COMINO MOLIDO X 500GR | C12: g | D12: 1 | E12: 0 | F12: 1 | G12: =+VLOOKUP(Tabla1103453454455456479116117118120740126148156186[[#This Row],[ArtÃ­culo]],Tabla34[#All],3,0) -> 60.0108 | H12: =+Tabla1103453454455456479116117118120740126148156186[[#This Row],[Coste Componente]]*Tabla1103453454455456479116117118120740126148156186[[#This Row],[Unidades]] -> 60.0108 | J12: IPOCONSUMO | K12: =+K10/K11 -> 23.341982
B13: PEREJIL CRESPO X KILO | C13: g | D13: 5 | E13: 0 | F13: 5 | G13: =+VLOOKUP(Tabla1103453454455456479116117118120740126148156186[[#This Row],[ArtÃ­culo]],Tabla34[#All],3,0) -> 8 | H13: =+Tabla1103453454455456479116117118120740126148156186[[#This Row],[Coste Componente]]*Tabla1103453454455456479116117118120740126148156186[[#This Row],[Unidades]] -> 40 | M13: Emplatado
B14: CEBOLLIN*KILO | C14: g | D14: 30 | E14: 0 | F14: 30 | G14: =+VLOOKUP(Tabla1103453454455456479116117118120740126148156186[[#This Row],[ArtÃ­culo]],Tabla34[#All],3,0) -> 16 | H14: =+Tabla1103453454455456479116117118120740126148156186[[#This Row],[Coste Componente]]*Tabla1103453454455456479116117118120740126148156186[[#This Row],[Unidades]] -> 480
B15: MAYONESA FRUCO GALON X3770G | C15: g | D15: 170 | E15: 0 | F15: 170 | G15: =+VLOOKUP(Tabla1103453454455456479116117118120740126148156186[[#This Row],[ArtÃ­culo]],Tabla34[#All],3,0) -> 26.272577 | H15: =+Tabla1103453454455456479116117118120740126148156186[[#This Row],[Coste Componente]]*Tabla1103453454455456479116117118120740126148156186[[#This Row],[Unidades]] -> 4466.338
B16: AJI DULCE X KILO | C16: g | D16: 15 | E16: 0 | F16: 15 | G16: =+VLOOKUP(Tabla1103453454455456479116117118120740126148156186[[#This Row],[ArtÃ­culo]],Tabla34[#All],3,0) -> 9.8 | H16: =+Tabla1103453454455456479116117118120740126148156186[[#This Row],[Coste Componente]]*Tabla1103453454455456479116117118120740126148156186[[#This Row],[Unidades]] -> 147
B17: CILANTRO LIMPIO X KILO | C17: g | D17: 5 | E17: 0 | F17: 5 | G17: =+VLOOKUP(Tabla1103453454455456479116117118120740126148156186[[#This Row],[ArtÃ­culo]],Tabla34[#All],3,0) -> 12 | H17: =+Tabla1103453454455456479116117118120740126148156186[[#This Row],[Coste Componente]]*Tabla1103453454455456479116117118120740126148156186[[#This Row],[Unidades]] -> 60
B18: LIMON TAHITI X KILO | C18: g | D18: 120 | E18: 0 | F18: 120 | G18: =+VLOOKUP(Tabla1103453454455456479116117118120740126148156186[[#This Row],[ArtÃ­culo]],Tabla34[#All],3,0) -> 4.5 | H18: =+Tabla1103453454455456479116117118120740126148156186[[#This Row],[Coste Componente]]*Tabla1103453454455456479116117118120740126148156186[[#This Row],[Unidades]] -> 540
B19: AJINOMOTO X KILO | C19: g | D19: 5 | E19: 0 | F19: 5 | G19: =+VLOOKUP(Tabla1103453454455456479116117118120740126148156186[[#This Row],[ArtÃ­culo]],Tabla34[#All],3,0) -> 13.401291 | H19: =+Tabla1103453454455456479116117118120740126148156186[[#This Row],[Coste Componente]]*Tabla1103453454455456479116117118120740126148156186[[#This Row],[Unidades]] -> 67.006457
B20: SAL REFISAL X 1000G | C20: g | D20: 6 | E20: 0 | F20: 6 | G20: =+VLOOKUP(Tabla1103453454455456479116117118120740126148156186[[#This Row],[ArtÃ­culo]],Tabla34[#All],3,0) -> 2.401 | H20: =+Tabla1103453454455456479116117118120740126148156186[[#This Row],[Coste Componente]]*Tabla1103453454455456479116117118120740126148156186[[#This Row],[Unidades]] -> 14.406
B21: PIMIENTA NEGRA MOLIDA BADIA 453GR | C21: g | D21: 1 | E21: 0 | F21: 1 | G21: =+VLOOKUP(Tabla1103453454455456479116117118120740126148156186[[#This Row],[ArtÃ­culo]],Tabla34[#All],3,0) -> 57.218062 | H21: =+Tabla1103453454455456479116117118120740126148156186[[#This Row],[Coste Componente]]*Tabla1103453454455456479116117118120740126148156186[[#This Row],[Unidades]] -> 57.218062
B22: CEBOLLA MORADA LIMPIA | C22: g | D22: 100 | E22: 0 | F22: 100 | G22: =+VLOOKUP(Tabla1103453454455456479116117118120740126148156186[[#This Row],[ArtÃ­culo]],Tabla34[#All],3,0) -> 4.7 | H22: =+Tabla1103453454455456479116117118120740126148156186[[#This Row],[Coste Componente]]*Tabla1103453454455456479116117118120740126148156186[[#This Row],[Unidades]] -> 470
H23: =SUBTOTAL(109,Tabla1103453454455456479116117118120740126148156186[Coste LÃ­nea]) -> 7224.8993
B26: SUB. ACEITE DE ACHIOTE | J26: ANALISIS RECETA | M26: Preparacion
B27: ArtÃ­culo | C27: Unidad Medida | D27: Unidades Netas | E27: % Merma | F27: Unidades | G27: Coste Componente | H27: Coste LÃ­nea | J27: COSTO DEL PLATO | K27: =SUM(Tabla1103453454455456479116117118120740126148156186184[Coste LÃ­nea]) -> 12627.899
B28: ACEITE VEGETAL X 20LT | C28: g | D28: 1000 | E28: 0 | F28: 1000 | G28: =+VLOOKUP(Tabla1103453454455456479116117118120740126148156186184[[#This Row],[ArtÃ­culo]],Tabla34[#All],3,0) -> 7.68385 | H28: =+Tabla1103453454455456479116117118120740126148156186184[[#This Row],[Coste Componente]]*Tabla1103453454455456479116117118120740126148156186184[[#This Row],[Unidades]] -> 7683.85 | J28: MARGEN DE ERROR DEL 10% | K28: =+K27*5% -> 631.39497
B29: ACHIOTE EN GRANO*1000 | C29: g | D29: 250 | E29: 0 | F29: 250 | G29: =+VLOOKUP(Tabla1103453454455456479116117118120740126148156186184[[#This Row],[ArtÃ­culo]],Tabla34[#All],3,0) -> 19.776197 | H29: =+Tabla1103453454455456479116117118120740126148156186184[[#This Row],[Coste Componente]]*Tabla1103453454455456479116117118120740126148156186184[[#This Row],[Unidades]] -> 4944.0494 | J29: COSTO + MARGEN ERROR | K29: =+K27+K28 -> 13259.294
H30: =SUBTOTAL(109,Tabla1103453454455456479116117118120740126148156186184[Coste LÃ­nea]) -> 12627.899 | J30: Rendimiento | K30: 1000
J31: IPOCONSUMO | K31: =+K29/K30 -> 13.259294
M32: Emplatado
B33: SUB. ACEVICHADA | J33: ANALISIS RECETA
B34: ArtÃ­culo | C34: Unidad Medida | D34: Unidades Netas | E34: % Merma | F34: Unidades | G34: Coste Componente | H34: Coste LÃ­nea | J34: COSTO DEL PLATO | K34: =SUM(Tabla1103453454455456479116117118120740126148156186185[Coste LÃ­nea]) -> 172105.01
B35: MAYONESA FRUCO GALON X3770G | C35: g | D35: 2810 | E35: 0 | F35: 2810 | G35: =+VLOOKUP(Tabla1103453454455456479116117118120740126148156186185[[#This Row],[ArtÃ­culo]],Tabla34[#All],3,0) -> 26.272577 | H35: =+Tabla1103453454455456479116117118120740126148156186185[[#This Row],[Coste Componente]]*Tabla1103453454455456479116117118120740126148156186185[[#This Row],[Unidades]] -> 73825.94 | J35: MARGEN DE ERROR DEL 10% | K35: =+K34*5% -> 8605.2504
B36: LIMON TAHITI X KILO | C36: g | D36: 1840 | E36: 78 | F36: 8363.637 | G36: =+VLOOKUP(Tabla1103453454455456479116117118120740126148156186185[[#This Row],[ArtÃ­culo]],Tabla34[#All],3,0) -> 4.5 | H36: =+Tabla1103453454455456479116117118120740126148156186185[[#This Row],[Coste Componente]]*Tabla1103453454455456479116117118120740126148156186185[[#This Row],[Unidades]] -> 37636.367 | J36: COSTO + MARGEN ERROR | K36: =+K34+K35 -> 180710.26
B37: SUB. PASTA ROCOTO | C37: g | D37: 1440 | E37: 0 | F37: 1440 | G37: =+VLOOKUP(Tabla1103453454455456479116117118120740126148156186185[[#This Row],[ArtÃ­culo]],Tabla34[#All],3,0) -> 40.42512 | H37: =+Tabla1103453454455456479116117118120740126148156186185[[#This Row],[Coste Componente]]*Tabla1103453454455456479116117118120740126148156186185[[#This Row],[Unidades]] -> 58212.172 | J37: Rendimiento | K37: 6300
B38: SUB. PASTA DE AJO | C38: g | D38: 70 | E38: 0 | F38: 70 | G38: =+VLOOKUP(Tabla1103453454455456479116117118120740126148156186185[[#This Row],[ArtÃ­culo]],Tabla34[#All],3,0) -> 14.257835 | H38: =+Tabla1103453454455456479116117118120740126148156186185[[#This Row],[Coste Componente]]*Tabla1103453454455456479116117118120740126148156186185[[#This Row],[Unidades]] -> 998.04848 | J38: IPOCONSUMO | K38: =+K36/K37 -> 28.684168
B39: SAL REFISAL X 1000G | C39: g | D39: 120 | E39: 0 | F39: 120 | G39: =+VLOOKUP(Tabla1103453454455456479116117118120740126148156186185[[#This Row],[ArtÃ­culo]],Tabla34[#All],3,0) -> 2.401 | H39: =+Tabla1103453454455456479116117118120740126148156186185[[#This Row],[Coste Componente]]*Tabla1103453454455456479116117118120740126148156186185[[#This Row],[Unidades]] -> 288.12
B40: PIMIENTA NEGRA MOLIDA BADIA 453GR | C40: g | D40: 20 | E40: 0 | F40: 20 | G40: =+VLOOKUP(Tabla1103453454455456479116117118120740126148156186185[[#This Row],[ArtÃ­culo]],Tabla34[#All],3,0) -> 57.218062 | H40: =+Tabla1103453454455456479116117118120740126148156186185[[#This Row],[Coste Componente]]*Tabla1103453454455456479116117118120740126148156186185[[#This Row],[Unidades]] -> 1144.3612
H41: =SUBTOTAL(109,Tabla1103453454455456479116117118120740126148156186185[Coste LÃ­nea]) -> 172105.01
B43: SUB. ADEREZO PICADILLO | J43: ANALISIS RECETA | M43: Preparacion
B44: ArtÃ­culo | C44: Unidad Medida | D44: Unidades Netas | E44: % Merma | F44: Unidades | G44: Coste Componente | H44: Coste LÃ­nea | J44: COSTO DEL PLATO | K44: =SUM(Tabla1103453454455456479116117118120740126148156186227[Coste LÃ­nea]) -> 3798.1416
B45: CEBOLLA BLANCA LIMPIA X KILO | C45: g | D45: 185 | E45: 0 | F45: 185 | G45: =+VLOOKUP(Tabla1103453454455456479116117118120740126148156186227[[#This Row],[ArtÃ­culo]],Tabla34[#All],3,0) -> 2.8 | H45: =+Tabla1103453454455456479116117118120740126148156186227[[#This Row],[Coste Componente]]*Tabla1103453454455456479116117118120740126148156186227[[#This Row],[Unidades]] -> 518 | J45: MARGEN DE ERROR DEL 10% | K45: =+K44*5% -> 189.90708
B46: AJI DULCE X KILO | C46: g | D46: 65 | E46: 0 | F46: 65 | G46: =+VLOOKUP(Tabla1103453454455456479116117118120740126148156186227[[#This Row],[ArtÃ­culo]],Tabla34[#All],3,0) -> 9.8 | H46: =+Tabla1103453454455456479116117118120740126148156186227[[#This Row],[Coste Componente]]*Tabla1103453454455456479116117118120740126148156186227[[#This Row],[Unidades]] -> 637 | J46: COSTO + MARGEN ERROR | K46: =+K44+K45 -> 3988.0487
B47: ALCAPARRA ALFRESCO X 500GR | C47: g | D47: 25 | E47: 0 | F47: 25 | G47: =+VLOOKUP(Tabla1103453454455456479116117118120740126148156186227[[#This Row],[ArtÃ­culo]],Tabla34[#All],3,0) -> 27.146 | H47: =+Tabla1103453454455456479116117118120740126148156186227[[#This Row],[Coste Componente]]*Tabla1103453454455456479116117118120740126148156186227[[#This Row],[Unidades]] -> 678.65 | J47: Rendimiento | K47: 2135
B48: ACEITE MESTRE OLEO X 3000CC | C48: g | D48: 80 | E48: 0 | F48: 80 | G48: =+VLOOKUP(Tabla1103453454455456479116117118120740126148156186227[[#This Row],[ArtÃ­culo]],Tabla34[#All],3,0) -> 18.859 | H48: =+Tabla1103453454455456479116117118120740126148156186227[[#This Row],[Coste Componente]]*Tabla1103453454455456479116117118120740126148156186227[[#This Row],[Unidades]] -> 1508.72 | J48: IPOCONSUMO | K48: =+K46/K47 -> 1.8679385
B49: SAL REFISAL X 1000G | C49: g | D49: 20 | E49: 0 | F49: 20 | G49: =+VLOOKUP(Tabla1103453454455456479116117118120740126148156186227[[#This Row],[ArtÃ­culo]],Tabla34[#All],3,0) -> 2.401 | H49: =+Tabla1103453454455456479116117118120740126148156186227[[#This Row],[Coste Componente]]*Tabla1103453454455456479116117118120740126148156186227[[#This Row],[Unidades]] -> 48.02 | M49: Emplatado
...

Sheet JUGOS NATURALES
B6: LIMONADA NATURAL | J6: ANALISIS RECETA | M6: Preparacion
B7: Ingrediente | C7: Und | D7: Cant. | E7: Columna1 | F7: Columna2 | G7: Costo | H7: Total costo | J7: COSTO DEL PLATO | K7: =SUM(Tabla1103453454455456479455868778695108117127136[Total costo]) -> 595.81166
B8: SUB. LIMON DESHIDRATADO | C8: g | D8: 2 | E8: 0 | F8: 2 | H8: =+Tabla1103453454455456479455868778695108117127136[[#This Row],[Costo]]*Tabla1103453454455456479455868778695108117127136[[#This Row],[Columna2]] -> 0 | J8: MARGEN DE ERROR DEL 10% | K8: =+K7*10% -> 59.581166
B9: SUB. ALMIBAR | C9: g | D9: 40 | E9: 0 | F9: 40 | G9: =+VLOOKUP(Tabla1103453454455456479455868778695108117127136[[#This Row],[Ingrediente]],Tabla34[#All],3,0) -> 5.7702916 | H9: =+Tabla1103453454455456479455868778695108117127136[[#This Row],[Costo]]*Tabla1103453454455456479455868778695108117127136[[#This Row],[Columna2]] -> 230.81166 | J9: COSTO + MARGEN ERROR | K9: =+K7+K8 -> 655.39283
B10: BOLSA DE HIELO IGLU 18 KG | C10: g | D10: 140 | E10: 0 | F10: 140 | G10: =+VLOOKUP(Tabla1103453454455456479455868778695108117127136[[#This Row],[Ingrediente]],Tabla34[#All],3,0) -> 1 | H10: =+Tabla1103453454455456479455868778695108117127136[[#This Row],[Costo]]*Tabla1103453454455456479455868778695108117127136[[#This Row],[Columna2]] -> 140 | J10: VALOR DE VENTA | K10: 10000
B11: AGUA EPM | C11: g | D11: 200 | E11: 0 | F11: 200 | H11: =+Tabla1103453454455456479455868778695108117127136[[#This Row],[Costo]]*Tabla1103453454455456479455868778695108117127136[[#This Row],[Columna2]] -> 0 | J11: IPOCONSUMO | K11: =+K10/1.08*0.08 -> 740.74074
B12: LIMON TAHITI *KILO BAR | C12: g | D12: 50 | E12: 0 | F12: 50 | G12: =+VLOOKUP(Tabla1103453454455456479455868778695108117127136[[#This Row],[Ingrediente]],Tabla34[#All],3,0) -> 4.5 | H12: =+Tabla1103453454455456479455868778695108117127136[[#This Row],[Costo]]*Tabla1103453454455456479455868778695108117127136[[#This Row],[Columna2]] -> 225 | J12: VALOR ANTES DE IPO | K12: =+K10-K11 -> 9259.2593
H13: =SUBTOTAL(109,Tabla1103453454455456479455868778695108117127136[Total costo]) -> 595.81166 | J13: MARGEN. | K13: =+K9/K12 -> 0.070782426
J14: GANANCIA | K14: =+K12-K9 -> 8603.8664
J15: MARGEN PORCENTUAL | K15: =+K14/K9 -> 13.127801
B18: LIMONADA DE COCO | J18: ANALISIS RECETA | M18: Preparacion
B19: Ingrediente | C19: Und | D19: Cant. | E19: Columna1 | F19: Columna2 | G19: Costo | H19: Total costo | J19: COSTO DEL PLATO | K19: =SUM(Tabla110345345445545647936465969788796109118128137[Total costo]) -> 4251.7502
B20: OCHUVA CON CAPACHO | C20: g | D20: 1 | E20: 0 | F20: 1 | G20: =+VLOOKUP(Tabla110345345445545647936465969788796109118128137[[#This Row],[Ingrediente]],Tabla34[#All],3,0) -> 9 | H20: =+Tabla110345345445545647936465969788796109118128137[[#This Row],[Costo]]*Tabla110345345445545647936465969788796109118128137[[#This Row],[Columna2]] -> 9 | J20: MARGEN DE ERROR DEL 10% | K20: =+K19*10% -> 425.17502
B21: PULPA DE COCO PAQUETE X10UND | C21: uds | D21: 1 | E21: 0 | F21: 1 | G21: =+VLOOKUP(Tabla110345345445545647936465969788796109118128137[[#This Row],[Ingrediente]],Tabla34[#All],3,0) -> 3300 | H21: =+Tabla110345345445545647936465969788796109118128137[[#This Row],[Costo]]*Tabla110345345445545647936465969788796109118128137[[#This Row],[Columna2]] -> 3300 | J21: COSTO + MARGEN ERROR | K21: =+K19+K20 -> 4676.9252
B22: SUB. COCO DESHIDRATADO | C22: g | D22: 10 | E22: 0 | F22: 10 | G22: =+VLOOKUP(Tabla110345345445545647936465969788796109118128137[[#This Row],[Ingrediente]],Tabla34[#All],3,0) -> 45.040724 | H22: =+Tabla110345345445545647936465969788796109118128137[[#This Row],[Costo]]*Tabla110345345445545647936465969788796109118128137[[#This Row],[Columna2]] -> 450.40724 | J22: VALOR DE VENTA | K22: 13000
B23: SUB. ALMIBAR | C23: g | D23: 10 | E23: 0 | F23: 10 | G23: =+VLOOKUP(Tabla110345345445545647936465969788796109118128137[[#This Row],[Ingrediente]],Tabla34[#All],3,0) -> 5.7702916 | H23: =+Tabla110345345445545647936465969788796109118128137[[#This Row],[Costo]]*Tabla110345345445545647936465969788796109118128137[[#This Row],[Columna2]] -> 57.702916 | J23: IPOCONSUMO | K23: =+K22/1.08*0.08 -> 962.96296
B24: SUB. ZUMO DE LIMON | C24: g | D24: 40 | E24: 0 | F24: 40 | G24: =+VLOOKUP(Tabla110345345445545647936465969788796109118128137[[#This Row],[Ingrediente]],Tabla34[#All],3,0) -> 10.866 | H24: =+Tabla110345345445545647936465969788796109118128137[[#This Row],[Costo]]*Tabla110345345445545647936465969788796109118128137[[#This Row],[Columna2]] -> 434.64 | J24: VALOR ANTES DE IPO | K24: =+K22-K23 -> 12037.037
H25: =SUBTOTAL(109,Tabla110345345445545647936465969788796109118128137[Total costo]) -> 4251.7502 | J25: MARGEN. | K25: =+K21/K24 -> 0.38854455
J26: GANANCIA | K26: =+K24-K21 -> 7360.1119
J27: MARGEN PORCENTUAL | K27: =+K26/K21 -> 1.5737074
B29: JUGO FRUTOS ROJOS | J29: ANALISIS RECETA | M29: Preparacion
B30: Ingrediente | C30: Und | D30: Cant. | E30: Columna1 | F30: Columna2 | G30: Costo | H30: Total costo | J30: COSTO DEL PLATO | K30: =SUM(Tabla11034534544554564793637476070798897110119129138[Total costo]) -> 2136.45
B31: AZUCAR MANUELITA BOLSA X 5LB | C31: g | D31: 30 | E31: 0 | F31: 30 | G31: =+VLOOKUP(Tabla11034534544554564793637476070798897110119129138[[#This Row],[Ingrediente]],Tabla34[#All],3,0) -> 4.8816667 | H31: =+Tabla11034534544554564793637476070798897110119129138[[#This Row],[Costo]]*Tabla11034534544554564793637476070798897110119129138[[#This Row],[Columna2]] -> 146.45 | J31: MARGEN DE ERROR DEL 10% | K31: =+K30*10% -> 213.645
B32: PULPA DE FRUTOS DE ARANDANOS*10UND | C32: uds | D32: 1 | E32: 0 | F32: 1 | G32: =+VLOOKUP(Tabla11034534544554564793637476070798897110119129138[[#This Row],[Ingrediente]],Tabla34[#All],3,0) -> 1900 | H32: =+Tabla11034534544554564793637476070798897110119129138[[#This Row],[Costo]]*Tabla11034534544554564793637476070798897110119129138[[#This Row],[Columna2]] -> 1900 | J32: COSTO + MARGEN ERROR | K32: =+K30+K31 -> 2350.095
B33: FLOR DE JAMAICA X KILO | C33: g | D33: 1 | E33: 0 | F33: 1 | G33: =+VLOOKUP(Tabla11034534544554564793637476070798897110119129138[[#This Row],[Ingrediente]],Tabla34[#All],3,0) -> 90 | H33: =+Tabla11034534544554564793637476070798897110119129138[[#This Row],[Costo]]*Tabla11034534544554564793637476070798897110119129138[[#This Row],[Columna2]] -> 90 | J33: VALOR DE VENTA | K33: 13000
B34: AGUA EPM | C34: g | D34: 200 | E34: 0 | F34: 200 | H34: =+Tabla11034534544554564793637476070798897110119129138[[#This Row],[Costo]]*Tabla11034534544554564793637476070798897110119129138[[#This Row],[Columna2]] -> 0 | J34: IPOCONSUMO | K34: =+K33/1.08*0.08 -> 962.96296
H35: =SUBTOTAL(109,Tabla11034534544554564793637476070798897110119129138[Total costo]) -> 2136.45 | J35: VALOR ANTES DE IPO | K35: =+K33-K34 -> 12037.037
J36: MARGEN. | K36: =+K32/K35 -> 0.19523866
J37: GANANCIA | K37: =+K35-K32 -> 9686.942
J38: MARGEN PORCENTUAL | K38: =+K37/K32 -> 4.1219364
B40: JUGO DE MANGO | J40: ANALISIS RECETA | M40: Preparacion
B41: Ingrediente | C41: Und | D41: Cant. | E41: Columna1 | F41: Columna2 | G41: Costo | H41: Total costo | J41: COSTO DEL PLATO | K41: =SUM(Tabla11034534544554564793638486171808998111120130139[Total costo]) -> 1969.1211
B42: PULPA MANGO 1000 GR | C42: uds | D42: 1 | E42: 0 | F42: 1 | G42: =+VLOOKUP(Tabla11034534544554564793638486171808998111120130139[[#This Row],[Ingrediente]],Tabla34[#All],3,0) -> 1800 | H42: =+Tabla11034534544554564793638486171808998111120130139[[#This Row],[Costo]]*Tabla11034534544554564793638486171808998111120130139[[#This Row],[Columna2]] -> 1800 | J42: MARGEN DE ERROR DEL 10% | K42: =+K41*10% -> 196.91211
B43: AZUCAR MANUELITA BOLSA X 5LB | C43: g | D43: 30 | E43: 0 | F43: 30 | G43: =+VLOOKUP(Tabla11034534544554564793638486171808998111120130139[[#This Row],[Ingrediente]],Tabla34[#All],3,0) -> 4.8816667 | H43: =+Tabla11034534544554564793638486171808998111120130139[[#This Row],[Costo]]*Tabla11034534544554564793638486171808998111120130139[[#This Row],[Columna2]] -> 146.45 | J43: COSTO + MARGEN ERROR | K43: =+K41+K42 -> 2166.0332
B44: SUB. MANGO DESHIDRATADO | C44: g | D44: 1 | E44: 0 | F44: 1 | G44: =+VLOOKUP(Tabla11034534544554564793638486171808998111120130139[[#This Row],[Ingrediente]],Tabla34[#All],3,0) -> 22.671053 | H44: =+Tabla11034534544554564793638486171808998111120130139[[#This Row],[Costo]]*Tabla11034534544554564793638486171808998111120130139[[#This Row],[Columna2]] -> 22.671053 | J44: VALOR DE VENTA | K44: 13500
B45: AGUA EPM | C45: g | D45: 200 | E45: 0 | F45: 200 | H45: =+Tabla11034534544554564793638486171808998111120130139[[#This Row],[Costo]]*Tabla11034534544554564793638486171808998111120130139[[#This Row],[Columna2]] -> 0 | J45: IPOCONSUMO | K45: =+K44/1.08*0.08 -> 1000
H46: =SUBTOTAL(109,Tabla11034534544554564793638486171808998111120130139[Total costo]) -> 1969.1211 | J46: VALOR ANTES DE IPO | K46: =+K44-K45 -> 12500
J47: MARGEN. | K47: =+K43/K46 -> 0.17328265
J48: GANANCIA | K48: =+K46-K43 -> 10333.967
J49: MARGEN PORCENTUAL | K49: =+K48/K43 -> 4.7709181
...

Sheet LANGOSTINOS
B6: LANGOSTINOS ARREBATADOS | J6: ANALISIS RECETA | M6: Preparacion
B7: Ingrediente | C7: Und | D7: Cant. | E7: Columna1 | F7: Columna2 | G7: Costo | H7: Total costo | J7: COSTO DEL PLATO | K7: =SUM(Tabla11034534544554564794558[Total costo]) -> 15030.98 | M7: 1. Apanar los langostinos y llevarlos a fritura profunda.
B8: LANGOSTINOS CRUDO 16/20 X UNIDAD | C8: uds | D8: 4 | E8: 0 | F8: 4 | G8: =+VLOOKUP(Tabla11034534544554564794558[[#This Row],[Ingrediente]],Tabla34[#All],3,0) -> 1600 | H8: =+Tabla11034534544554564794558[[#This Row],[Costo]]*Tabla11034534544554564794558[[#This Row],[Columna2]] -> 6400 | J8: MARGEN DE ERROR DEL 10% | K8: =+K7*10% -> 1503.098 | M8: 2. Llevar a una manga pastelera el puré de papa (boquilla rizada).
B9: QUESO ALPINA PARMESANO RAYADO 2.5 L | C9: g | D9: 30 | E9: 0 | F9: 30 | G9: =+VLOOKUP(Tabla11034534544554564794558[[#This Row],[Ingrediente]],Tabla34[#All],3,0) -> 60.9875 | H9: =+Tabla11034534544554564794558[[#This Row],[Costo]]*Tabla11034534544554564794558[[#This Row],[Columna2]] -> 1829.625 | J9: COSTO + MARGEN ERROR | K9: =+K7+K8 -> 16534.078 | M9: 3. Para la salsa llevamos en un wok la crema de leche, parmesano, pasta de rocoto, sal (punto de napa)
B10: SUB. PURE DE PAPA | C10: g | D10: 150 | E10: 0 | F10: 150 | G10: =+VLOOKUP(Tabla11034534544554564794558[[#This Row],[Ingrediente]],Tabla34[#All],3,0) -> 16.73096 | H10: =+Tabla11034534544554564794558[[#This Row],[Costo]]*Tabla11034534544554564794558[[#This Row],[Columna2]] -> 2509.6441 | J10: VALOR DE VENTA | K10: 56000
B11: SUB. PASTA ROCOTO | C11: g | D11: 40 | E11: 0 | F11: 40 | G11: =+VLOOKUP(Tabla11034534544554564794558[[#This Row],[Ingrediente]],Tabla34[#All],3,0) -> 40.42512 | H11: =+Tabla11034534544554564794558[[#This Row],[Costo]]*Tabla11034534544554564794558[[#This Row],[Columna2]] -> 1617.0048 | J11: IPOCONSUMO | K11: =+K10/1.08*0.08 -> 4148.1481
B12: SUB. HUEVO BATIDO | C12: g | D12: 30 | E12: 0 | F12: 30 | G12: =+VLOOKUP(Tabla11034534544554564794558[[#This Row],[Ingrediente]],Tabla34[#All],3,0) -> 18.782609 | H12: =+Tabla11034534544554564794558[[#This Row],[Costo]]*Tabla11034534544554564794558[[#This Row],[Columna2]] -> 563.47826 | J12: VALOR ANTES DE IPO | K12: =+K10-K11 -> 51851.852 | M12: Emplatado
B13: SUB. CHIMICHURRY ROJO | C13: g | D13: 20 | E13: 0 | F13: 20 | G13: =+VLOOKUP(Tabla11034534544554564794558[[#This Row],[Ingrediente]],Tabla34[#All],3,0) -> 20.160619 | H13: =+Tabla11034534544554564794558[[#This Row],[Costo]]*Tabla11034534544554564794558[[#This Row],[Columna2]] -> 403.21238 | J13: MARGEN. | K13: =+K9/K12 -> 0.3188715 | M13: 1. En una parrilla redonda y caliente poner el puré de papa con la ayuda de la manga pastelera.
B14: SUB. ACEVICHADA | C14: g | D14: 15 | E14: 0 | F14: 15 | G14: =+VLOOKUP(Tabla11034534544554564794558[[#This Row],[Ingrediente]],Tabla34[#All],3,0) -> 26.416185 | H14: =+Tabla11034534544554564794558[[#This Row],[Costo]]*Tabla11034534544554564794558[[#This Row],[Columna2]] -> 396.24277 | J14: GANANCIA | K14: =+K12-K9 -> 35317.774 | M14: 2. En los costados del puré colocar la salsa hecha en el wok.
B15: CREMA DE LECHE X 9700G | C15: g | D15: 20 | E15: 0 | F15: 20 | G15: =+VLOOKUP(Tabla11034534544554564794558[[#This Row],[Ingrediente]],Tabla34[#All],3,0) -> 19.804167 | H15: =+Tabla11034534544554564794558[[#This Row],[Costo]]*Tabla11034534544554564794558[[#This Row],[Columna2]] -> 396.08333 | J15: MARGEN PORCENTUAL | K15: =+K14/K9 -> 2.1360595 | M15: 3. Sobre la salsa le agregamos la acevichada realizando líneas con la ayuda de un tetero.
B16: BROTES DE RABANO 50 | C16: g | D16: 1 | E16: 0 | F16: 1 | G16: =+VLOOKUP(Tabla11034534544554564794558[[#This Row],[Ingrediente]],Tabla34[#All],3,0) -> 307.5 | H16: =+Tabla11034534544554564794558[[#This Row],[Costo]]*Tabla11034534544554564794558[[#This Row],[Columna2]] -> 307.5 | M16: Decoramos con mézclum, chimichurri y esparcimos ajonjolí.
B17: HARINA DE TRIGO HAZ DE OROS BOLSA X550g | C17: g | D17: 60 | E17: 0 | F17: 60 | G17: =+VLOOKUP(Tabla11034534544554564794558[[#This Row],[Ingrediente]],Tabla34[#All],3,0) -> 4.2672 | H17: =+Tabla11034534544554564794558[[#This Row],[Costo]]*Tabla11034534544554564794558[[#This Row],[Columna2]] -> 256.032
B18: COCO RALLADO NRO1 IPRODESA XK CD21 | C18: g | D18: 5 | E18: 0 | F18: 5 | G18: =+VLOOKUP(Tabla11034534544554564794558[[#This Row],[Ingrediente]],Tabla34[#All],3,0) -> 37.6305 | H18: =+Tabla11034534544554564794558[[#This Row],[Costo]]*Tabla11034534544554564794558[[#This Row],[Columna2]] -> 188.1525
B19: VINO TINTO CAVIC TETRAPACK X 1LT | C19: g | D19: 5 | E19: 0 | F19: 5 | G19: =+VLOOKUP(Tabla11034534544554564794558[[#This Row],[Ingrediente]],Tabla34[#All],3,0) -> 15.193341 | H19: =+Tabla11034534544554564794558[[#This Row],[Costo]]*Tabla11034534544554564794558[[#This Row],[Columna2]] -> 75.966706
B20: AJONJOLI NEGRO X 500GR | C20: g | D20: 1 | E20: 0 | F20: 1 | G20: =+VLOOKUP(Tabla11034534544554564794558[[#This Row],[Ingrediente]],Tabla34[#All],3,0) -> 73.78 | H20: =+Tabla11034534544554564794558[[#This Row],[Costo]]*Tabla11034534544554564794558[[#This Row],[Columna2]] -> 73.78
B21: SUB. PASTA DE AJO | C21: g | D21: 1 | E21: 0 | F21: 1 | G21: =+VLOOKUP(Tabla11034534544554564794558[[#This Row],[Ingrediente]],Tabla34[#All],3,0) -> 14.257835 | H21: =+Tabla11034534544554564794558[[#This Row],[Costo]]*Tabla11034534544554564794558[[#This Row],[Columna2]] -> 14.257835
H22: =SUBTOTAL(109,Tabla11034534544554564794558[Total costo]) -> 15030.98
B24: LANGOSTINOS EN COCO Y CURRY | J24: ANALISIS RECETA | M24: Preparacion
B25: Ingrediente | C25: Und | D25: Cant. | E25: Columna1 | F25: Columna2 | G25: Costo | H25: Total costo | J25: COSTO DEL PLATO | K25: =SUM(Tabla1103453454455456479364659[Total costo]) -> 12302.781 | M25: 1. Salteamos los langostinos previamente sazonados, aparte sofreímos la cebolla, agregamos el curry, crema de coco y la crema de leche para la salsa.
B26: LANGOSTINOS CRUDO 16/20 X UNIDAD | C26: uds | D26: 4 | E26: 0 | F26: 4 | G26: =+VLOOKUP(Tabla1103453454455456479364659[[#This Row],[Ingrediente]],Tabla34[#All],3,0) -> 1600 | H26: =+Tabla1103453454455456479364659[[#This Row],[Costo]]*Tabla1103453454455456479364659[[#This Row],[Columna2]] -> 6400 | J26: MARGEN DE ERROR DEL 10% | K26: =+K25*10% -> 1230.2781 | M26: 2. Calentamos el puré y agregamos tomate perla y queso parmesano
B27: SUB. PURE DE PAPA | C27: g | D27: 150 | E27: 0 | F27: 150 | G27: =+VLOOKUP(Tabla1103453454455456479364659[[#This Row],[Ingrediente]],Tabla34[#All],3,0) -> 16.73096 | H27: =+Tabla1103453454455456479364659[[#This Row],[Costo]]*Tabla1103453454455456479364659[[#This Row],[Columna2]] -> 2509.6441 | J27: COSTO + MARGEN ERROR | K27: =+K25+K26 -> 13533.059
B28: CREMA DE COCO ROLAND X 960 GR | C28: g | D28: 30 | E28: 0 | F28: 30 | G28: =+VLOOKUP(Tabla1103453454455456479364659[[#This Row],[Ingrediente]],Tabla34[#All],3,0) -> 39.071701 | H28: =+Tabla1103453454455456479364659[[#This Row],[Costo]]*Tabla1103453454455456479364659[[#This Row],[Columna2]] -> 1172.151 | J28: VALOR DE VENTA | K28: 56000 | M28: Emplatado
B29: CREMA DE LECHE X 9700G | C29: g | D29: 60 | E29: 0 | F29: 60 | G29: =+VLOOKUP(Tabla1103453454455456479364659[[#This Row],[Ingrediente]],Tabla34[#All],3,0) -> 19.804167 | H29: =+Tabla1103453454455456479364659[[#This Row],[Costo]]*Tabla1103453454455456479364659[[#This Row],[Columna2]] -> 1188.25 | J29: IPOCONSUMO | K29: =+K28/1.08*0.08 -> 4148.1481 | M29: 1. En el centro del plato colocamos el puré.
B30: QUESO ALPINA PARMESANO RAYADO 2.5 L | C30: g | D30: 5 | E30: 0 | F30: 5 | G30: =+VLOOKUP(Tabla1103453454455456479364659[[#This Row],[Ingrediente]],Tabla34[#All],3,0) -> 60.9875 | H30: =+Tabla1103453454455456479364659[[#This Row],[Costo]]*Tabla1103453454455456479364659[[#This Row],[Columna2]] -> 304.9375 | J30: VALOR ANTES DE IPO | K30: =+K28-K29 -> 51851.852 | M30: 2. Coronamos con los cuatro langostinos
B31: BROTES DE RABANO 50 | C31: g | D31: 1 | E31: 0 | F31: 1 | G31: =+VLOOKUP(Tabla1103453454455456479364659[[#This Row],[Ingrediente]],Tabla34[#All],3,0) -> 307.5 | H31: =+Tabla1103453454455456479364659[[#This Row],[Costo]]*Tabla1103453454455456479364659[[#This Row],[Columna2]] -> 307.5 | J31: MARGEN. | K31: =+K27/K30 -> 0.26099471 | M31: 3. Servimos la salsa aparte
B32: SUB. TIERRA DE ARVERJA | C32: g | D32: 5 | E32: 0 | F32: 5 | G32: =+VLOOKUP(Tabla1103453454455456479364659[[#This Row],[Ingrediente]],Tabla34[#All],3,0) -> 44.585987 | H32: =+Tabla1103453454455456479364659[[#This Row],[Costo]]*Tabla1103453454455456479364659[[#This Row],[Columna2]] -> 222.92994 | J32: GANANCIA | K32: =+K30-K27 -> 38318.793 | M32: 4. La tierra de lentejas va alrededor del puré, los tomates perla y las flores comestibles
B33: TOMATE PERLA X KILO | C33: g | D33: 5.0000001 | E33: 5 | F33: 5.263158 | G33: =+VLOOKUP(Tabla1103453454455456479364659[[#This Row],[Ingrediente]],Tabla34[#All],3,0) -> 37.5 | H33: =+Tabla1103453454455456479364659[[#This Row],[Costo]]*Tabla1103453454455456479364659[[#This Row],[Columna2]] -> 197.36843 | J33: MARGEN PORCENTUAL | K33: =+K32/K27 -> 2.8314953
B34: CURRY BADIA X454G | C34: g | D34: 5 | E34: 0 | F34: 5 | G34: =+VLOOKUP(Tabla1103453454455456479364659[[#This Row],[Ingrediente]],Tabla34[#All],3,0) -> 0 | H34: =+Tabla1103453454455456479364659[[#This Row],[Costo]]*Tabla1103453454455456479364659[[#This Row],[Columna2]] -> 0
H35: =SUBTOTAL(109,Tabla1103453454455456479364659[Total costo]) -> 12302.781
B38: LANGOSTINOS TIMBIQUI | J38: ANALISIS RECETA | M38: Preparacion
B39: Ingrediente | C39: Und | D39: Cant. | E39: Columna1 | F39: Columna2 | G39: Costo | H39: Total costo | J39: COSTO DEL PLATO | K39: =SUM(Tabla110345345445545647936374760[Total costo]) -> 13086.055
B40: LANGOSTINOS CRUDO 16/20 X UNIDAD | C40: uds | D40: 4 | E40: 0 | F40: 4 | G40: =+VLOOKUP(Tabla110345345445545647936374760[[#This Row],[Ingrediente]],Tabla34[#All],3,0) -> 1600 | H40: =+Tabla110345345445545647936374760[[#This Row],[Costo]]*Tabla110345345445545647936374760[[#This Row],[Columna2]] -> 6400 | J40: MARGEN DE ERROR DEL 10% | K40: =+K39*10% -> 1308.6055
